Workbook
Name Skills: Powers!$C$2:$C$108
Name Factions: Factions!$B$2:$B$100
Name Weapons: Powers!$A$2:$A$108
Name Armour: Powers!$B$2:$B$108

Sheet Units
A1: Id | B1: Name | C1: Unit | D1: Include | E1: Faction | F1: Class | G1: Comparison Class | H1: Base Block | I1: Tier | J1: Cost | K1: Equips | L1: Number | M1: Movement | N1: Melee Hit | O1: Ranged Hit | P1: Attacks | Q1: HP | R1: Block | S1: Powers | T1: TCR | U1: Example Equip Powers | V1: SNCPS | W1: Spells | X1: Banners | Y1: Spears | Z1: Axes | AA1: Clubs | AB1: Offhand | AC1: Shields | AD1: Ranged | AE1: Move Colour | AF1: Melee Colour | AG1: Ranged Colour | AH1: Attacks Colour | AI1: HP Colour | AJ1: Block Colour | AK1: L1 Colour | AL1: L2 Colour | AM1: L1 Text Colour | AN1: L2 Text Colour | AO1: Faction Icon | AP1: Min Speed | AQ1: Total Wounds | AR1: Predicted Hits to Kill | AS1: EAPM | AT1: EAPR | AU1: Poison Mult | AV1: Ret Bonus | AW1: Predicted Hits per Round | AX1: Base Score | AY1: Exclude From Averages
A2: 03_1_5 | B2: Fodder | C2: =concatenate(E2," ",B2) -> Boneborn Fodder | D2: TRUE | E2: Boneborn | F2: Skeletons | G2: Chaff | H2: 6 | I2: 1 | J2: 1 | L2: 6 | M2: 1 | N2: 6 | O2: - | P2: 1 | Q2: 1 | R2: 5 | S2: <b>Unstable</b> - Instead of rolling to flee, lose 1 extra wound | T2: 3 | AE2: #000000 | AF2: #cc0000 | AG2: #000000 | AH2: #000000 | AI2: #000000 | AJ2: #000000 | AK2: {=INDEX(Factions!C:C, MATCH(E2, Factions!B:B, 0))} -> #e0e0d3 | AL2: {=INDEX(Factions!D:D, MATCH(E2, Factions!B:B, 0))} -> #4d4d4d | AM2: {=INDEX(Factions!E:E, MATCH(E2, Factions!B:B, 0))} -> #000000 | AN2: {=INDEX(Factions!F:F, MATCH(E2, Factions!B:B, 0))} -> #ffffff | AO2: {=concat(INDEX(Factions!G:G, MATCH(E2, Factions!B:B, 0)),".png")} -> skellies.png | AP2: =IFERROR(__xludf.DUMMYFUNCTION("MIN(FILTER(M2:M1098, F2:F1098=F2))"),1.0) -> 1 | AQ2: =Q2*L2 -> 6 | AR2: =IFERROR(__xludf.DUMMYFUNCTION("IF(and(REGEXMATCH(S2,""Vengence""),not(REGEXMATCH(S2, ""Protective Markings""))),AQ2,AQ2 * 6 / iferror(R2-1,6))"),9.0) -> 9 | AS2: =0 + if(P2="2d6",7,if(P2="d6",3.5,if(P2="d3",1.5,if(P2="2x2",4,if(P2="2x3",6,P2))))) -> 1 | AT2: =AS2*L2 -> 6 | AU2: =IFERROR(__xludf.DUMMYFUNCTION("IF(REGEXMATCH(S2,""<b>Poison</b>""),1+((1/(7-N2))/3),1)"),1.0) -> 1 | AV2: =IFERROR(__xludf.DUMMYFUNCTION("IF(REGEXMATCH(S2,""Vengence""),(7 - R2) / 3,0)"),0.0) -> 0 | AW2: =AV2 + (AT2*(7-N2)/6)*AU2 -> 1 | AX2: =AR2+(AW2*1.5) -> 10.5 | AY2: =IFERROR(__xludf.DUMMYFUNCTION("if(regexmatch(G2,""Mage|War Machine""),true,false)"),FALSE) -> FALSE
A3: 03_1_6 | B3: Shieldbearers | C3: =concatenate(E3," ",B3) -> Boneborn Shieldbearers | D3: TRUE | E3: Boneborn | F3: Skeletons | G3: Heavy Infantry | H3: 6 | I3: 1 | J3: 2 | L3: 6 | M3: 1 | N3: 5 | O3: - | P3: 1 | Q3: 1 | R3: 4 | S3: <b>Unstable</b> - Instead of rolling to flee, lose 1 extra wound | T3: 4 | Y3: 1 | AC3: 1 | AE3: #000000 | AF3: #cc0000 | AG3: #000000 | AH3: #000000 | AI3: #000000 | AJ3: #2b9800 | AK3: {=INDEX(Factions!C:C, MATCH(E3, Factions!B:B, 0))} -> #e0e0d3 | AL3: {=INDEX(Factions!D:D, MATCH(E3, Factions!B:B, 0))} -> #4d4d4d | AM3: {=INDEX(Factions!E:E, MATCH(E3, Factions!B:B, 0))} -> #000000 | AN3: {=INDEX(Factions!F:F, MATCH(E3, Factions!B:B, 0))} -> #ffffff | AO3: {=concat(INDEX(Factions!G:G, MATCH(E3, Factions!B:B, 0)),".png")} -> skellies.png | AP3: =IFERROR(__xludf.DUMMYFUNCTION("MIN(FILTER(M3:M1098, F3:F1098=F3))"),1.0) -> 1 | AQ3: =Q3*L3 -> 6 | AR3: =IFERROR(__xludf.DUMMYFUNCTION("IF(and(REGEXMATCH(S3,""Vengence""),not(REGEXMATCH(S3, ""Protective Markings""))),AQ3,AQ3 * 6 / iferror(R3-1,6))"),12.0) -> 12 | AS3: =0 + if(P3="2d6",7,if(P3="d6",3.5,if(P3="d3",1.5,if(P3="2x2",4,if(P3="2x3",6,P3))))) -> 1 | AT3: =AS3*L3 -> 6 | AU3: =IFERROR(__xludf.DUMMYFUNCTION("IF(REGEXMATCH(S3,""<b>Poison</b>""),1+((1/(7-N3))/3),1)"),1.0) -> 1 | AV3: =IFERROR(__xludf.DUMMYFUNCTION("IF(REGEXMATCH(S3,""Vengence""),(7 - R3) / 3,0)"),0.0) -> 0 | AW3: =AV3 + (AT3*(7-N3)/6)*AU3 -> 2 | AX3: =AR3+(AW3*1.5) -> 15 | AY3: =IFERROR(__xludf.DUMMYFUNCTION("if(regexmatch(G3,""Mage|War Machine""),true,false)"),FALSE) -> FALSE
A4: 03_1_1 | B4: Warriors | C4: =concatenate(E4," ",B4) -> Boneborn Warriors | D4: TRUE | E4: Boneborn | F4: Skeletons | G4: Warriors | H4: 6 | I4: 1 | J4: 2 | L4: 6 | M4: 1 | N4: 4 | O4: - | P4: 1 | Q4: 1 | R4: 5 | S4: <b>Unstable</b> - Instead of rolling to flee, lose 1 extra wound | T4: 4 | Y4: 1 | Z4: 1 | AA4: 1 | AB4: 1 | AC4: 1 | AE4: #000000 | AF4: #000000 | AG4: #000000 | AH4: #000000 | AI4: #000000 | AJ4: #000000 | AK4: {=INDEX(Factions!C:C, MATCH(E4, Factions!B:B, 0))} -> #e0e0d3 | AL4: {=INDEX(Factions!D:D, MATCH(E4, Factions!B:B, 0))} -> #4d4d4d | AM4: {=INDEX(Factions!E:E, MATCH(E4, Factions!B:B, 0))} -> #000000 | AN4: {=INDEX(Factions!F:F, MATCH(E4, Factions!B:B, 0))} -> #ffffff | AO4: {=concat(INDEX(Factions!G:G, MATCH(E4, Factions!B:B, 0)),".png")} -> skellies.png | AP4: =IFERROR(__xludf.DUMMYFUNCTION("MIN(FILTER(M4:M1098, F4:F1098=F4))"),1.0) -> 1 | AQ4: =Q4*L4 -> 6 | AR4: =IFERROR(__xludf.DUMMYFUNCTION("IF(and(REGEXMATCH(S4,""Vengence""),not(REGEXMATCH(S4, ""Protective Markings""))),AQ4,AQ4 * 6 / iferror(R4-1,6))"),9.0) -> 9 | AS4: =0 + if(P4="2d6",7,if(P4="d6",3.5,if(P4="d3",1.5,if(P4="2x2",4,if(P4="2x3",6,P4))))) -> 1 | AT4: =AS4*L4 -> 6 | AU4: =IFERROR(__xludf.DUMMYFUNCTION("IF(REGEXMATCH(S4,""<b>Poison</b>""),1+((1/(7-N4))/3),1)"),1.0) -> 1 | AV4: =IFERROR(__xludf.DUMMYFUNCTION("IF(REGEXMATCH(S4,""Vengence""),(7 - R4) / 3,0)"),0.0) -> 0 | AW4: =AV4 + (AT4*(7-N4)/6)*AU4 -> 3 | AX4: =AR4+(AW4*1.5) -> 13.5 | AY4: =IFERROR(__xludf.DUMMYFUNCTION("if(regexmatch(G4,""Mage|War Machine""),true,false)"),FALSE) -> FALSE
A5: 03_1_2 | B5: Archers | C5: =concatenate(E5," ",B5) -> Boneborn Archers | D5: TRUE | E5: Boneborn | F5: Skeletons | G5: Archers | H5: 6 | I5: 1 | J5: 2 | L5: 6 | M5: 1 | N5: 5 | O5: 4 | P5: 1 | Q5: 1 | R5: 6 | S5: <b>Unstable</b> - Instead of rolling to flee, lose 1 extra wound | T5: 3 | AD5: 1 | AE5: #000000 | AF5: #cc0000 | AG5: #2b9800 | AH5: #000000 | AI5: #000000 | AJ5: #cc0000 | AK5: {=INDEX(Factions!C:C, MATCH(E5, Factions!B:B, 0))} -> #e0e0d3 | AL5: {=INDEX(Factions!D:D, MATCH(E5, Factions!B:B, 0))} -> #4d4d4d | AM5: {=INDEX(Factions!E:E, MATCH(E5, Factions!B:B, 0))} -> #000000 | AN5: {=INDEX(Factions!F:F, MATCH(E5, Factions!B:B, 0))} -> #ffffff | AO5: {=concat(INDEX(Factions!G:G, MATCH(E5, Factions!B:B, 0)),".png")} -> skellies.png | AP5: =IFERROR(__xludf.DUMMYFUNCTION("MIN(FILTER(M5:M1098, F5:F1098=F5))"),1.0) -> 1 | AQ5: =Q5*L5 -> 6 | AR5: =IFERROR(__xludf.DUMMYFUNCTION("IF(and(REGEXMATCH(S5,""Vengence""),not(REGEXMATCH(S5, ""Protective Markings""))),AQ5,AQ5 * 6 / iferror(R5-1,6))"),7.2) -> 7.2 | AS5: =0 + if(P5="2d6",7,if(P5="d6",3.5,if(P5="d3",1.5,if(P5="2x2",4,if(P5="2x3",6,P5))))) -> 1 | AT5: =AS5*L5 -> 6 | AU5: =IFERROR(__xludf.DUMMYFUNCTION("IF(REGEXMATCH(S5,""<b>Poison</b>""),1+((1/(7-N5))/3),1)"),1.0) -> 1 | AV5: =IFERROR(__xludf.DUMMYFUNCTION("IF(REGEXMATCH(S5,""Vengence""),(7 - R5) / 3,0)"),0.0) -> 0 | AW5: =AV5 + (AT5*(7-N5)/6)*AU5 -> 2 | AX5: =AR5+(AW5*1.5) -> 10.2 | AY5: =IFERROR(__xludf.DUMMYFUNCTION("if(regexmatch(G5,""Mage|War Machine""),true,false)"),FALSE) -> FALSE
A6: 03_1_4 | B6: Wights | C6: =concatenate(E6," ",B6) -> Boneborn Wights | D6: TRUE | E6: Boneborn | F6: Skeletons | G6: Heavy Infantry | H6: 6 | I6: 1 | J6: 3 | L6: 6 | M6: 1 | N6: 5 | O6: - | P6: 1 | Q6: 1 | R6: 4 | S6: <b>Unstable</b> - Instead of rolling to flee, lose 1 extra wound <b>Terrifying</b> - At the start of each round of combat, all enemy units in combat with it must roll to flee. If they flee out of combat, no combat takes place. | T6: 5 | Y6: 1 | Z6: 1 | AA6: 1 | AB6: 1 | AC6: 1 | AE6: #000000 | AF6: #cc0000 | AG6: #000000 | AH6: #000000 | AI6: #000000 | AJ6: #2b9800 | AK6: {=INDEX(Factions!C:C, MATCH(E6, Factions!B:B, 0))} -> #e0e0d3 | AL6: {=INDEX(Factions!D:D, MATCH(E6, Factions!B:B, 0))} -> #4d4d4d | AM6: {=INDEX(Factions!E:E, MATCH(E6, Factions!B:B, 0))} -> #000000 | AN6: {=INDEX(Factions!F:F, MATCH(E6, Factions!B:B, 0))} -> #ffffff | AO6: {=concat(INDEX(Factions!G:G, MATCH(E6, Factions!B:B, 0)),".png")} -> skellies.png | AP6: =IFERROR(__xludf.DUMMYFUNCTION("MIN(FILTER(M6:M1098, F6:F1098=F6))"),1.0) -> 1 | AQ6: =Q6*L6 -> 6 | AR6: =IFERROR(__xludf.DUMMYFUNCTION("IF(and(REGEXMATCH(S6,""Vengence""),not(REGEXMATCH(S6, ""Protective Markings""))),AQ6,AQ6 * 6 / iferror(R6-1,6))"),12.0) -> 12 | AS6: =0 + if(P6="2d6",7,if(P6="d6",3.5,if(P6="d3",1.5,if(P6="2x2",4,if(P6="2x3",6,P6))))) -> 1 | AT6: =AS6*L6 -> 6 | AU6: =IFERROR(__xludf.DUMMYFUNCTION("IF(REGEXMATCH(S6,""<b>Poison</b>""),1+((1/(7-N6))/3),1)"),1.0) -> 1 | AV6: =IFERROR(__xludf.DUMMYFUNCTION("IF(REGEXMATCH(S6,""Vengence""),(7 - R6) / 3,0)"),0.0) -> 0 | AW6: =AV6 + (AT6*(7-N6)/6)*AU6 -> 2 | AX6: =AR6+(AW6*1.5) -> 15 | AY6: =IFERROR(__xludf.DUMMYFUNCTION("if(regexmatch(G6,""Mage|War Machine""),true,false)"),FALSE) -> FALSE
A7: 03_1_3 | B7: Revenants | C7: =concatenate(E7," ",B7) -> Boneborn Revenants | D7: TRUE | E7: Boneborn | F7: Skeletons | G7: Infantry | H7: 6 | I7: 1 | J7: 3 | L7: 6 | M7: 1 | N7: 4 | O7: - | P7: 1 | Q7: 1 | R7: 5 | S7: <b>Unstable</b> - Instead of rolling to flee, lose 1 extra wound <b>Revenants</b> - After combat, add a new model for each enemy model that died. Limited to the starting size. | T7: 5 | Z7: 1 | AA7: 1 | AB7: 1 | AC7: 1 | AE7: #000000 | AF7: #000000 | AG7: #000000 | AH7: #000000 | AI7: #000000 | AJ7: #000000 | AK7: {=INDEX(Factions!C:C, MATCH(E7, Factions!B:B, 0))} -> #e0e0d3 | AL7: {=INDEX(Factions!D:D, MATCH(E7, Factions!B:B, 0))} -> #4d4d4d | AM7: {=INDEX(Factions!E:E, MATCH(E7, Factions!B:B, 0))} -> #000000 | AN7: {=INDEX(Factions!F:F, MATCH(E7, Factions!B:B, 0))} -> #ffffff | AO7: {=concat(INDEX(Factions!G:G, MATCH(E7, Factions!B:B, 0)),".png")} -> skellies.png | AP7: =IFERROR(__xludf.DUMMYFUNCTION("MIN(FILTER(M7:M1098, F7:F1098=F7))"),1.0) -> 1 | AQ7: =Q7*L7 -> 6 | AR7: =IFERROR(__xludf.DUMMYFUNCTION("IF(and(REGEXMATCH(S7,""Vengence""),not(REGEXMATCH(S7, ""Protective Markings""))),AQ7,AQ7 * 6 / iferror(R7-1,6))"),9.0) -> 9 | AS7: =0 + if(P7="2d6",7,if(P7="d6",3.5,if(P7="d3",1.5,if(P7="2x2",4,if(P7="2x3",6,P7))))) -> 1 | AT7: =AS7*L7 -> 6 | AU7: =IFERROR(__xludf.DUMMYFUNCTION("IF(REGEXMATCH(S7,""<b>Poison</b>""),1+((1/(7-N7))/3),1)"),1.0) -> 1 | AV7: =IFERROR(__xludf.DUMMYFUNCTION("IF(REGEXMATCH(S7,""Vengence""),(7 - R7) / 3,0)"),0.0) -> 0 | AW7: =AV7 + (AT7*(7-N7)/6)*AU7 -> 3 | AX7: =AR7+(AW7*1.5) -> 13.5 | AY7: =IFERROR(__xludf.DUMMYFUNCTION("if(regexmatch(G7,""Mage|War Machine""),true,false)"),FALSE) -> FALSE
A8: 03_2A_1 | B8: Tomb Titan | C8: =concatenate(E8," ",B8) -> Boneborn Tomb Titan | D8: TRUE | E8: Boneborn | F8: Bonegiant | G8: Monster | H8: 5 | I8: 2 | L8: 1 | M8: 1 | N8: 3 | O8: - | P8: 5 | Q8: 5 | R8: 4 | S8: <b>Unstable</b> - Instead of rolling to flee, lose 1 extra wound <b>Mighty Cleave</b> - In combat this unit makes its attacks against all adjacent enemy units. Roll separately for each. If they are not in combat, they take damage but are not included in combat resolution and do not strike back. <b>Well Prepared</b> - Equipment costs 1 less. | T8: 6 | U8: <b>AP 1</b> | Z8: 2 | AA8: 2 | AE8: #000000 | AF8: #2b9800 | AG8: #000000 | AH8: #2b9800 | AI8: #2b9800 | AJ8: #2b9800 | AK8: {=INDEX(Factions!C:C, MATCH(E8, Factions!B:B, 0))} -> #e0e0d3 | AL8: {=INDEX(Factions!D:D, MATCH(E8, Factions!B:B, 0))} -> #4d4d4d | AM8: {=INDEX(Factions!E:E, MATCH(E8, Factions!B:B, 0))} -> #000000 | AN8: {=INDEX(Factions!F:F, MATCH(E8, Factions!B:B, 0))} -> #ffffff | AO8: {=concat(INDEX(Factions!G:G, MATCH(E8, Factions!B:B, 0)),".png")} -> skellies.png | AP8: =IFERROR(__xludf.DUMMYFUNCTION("MIN(FILTER(M8:M1098, F8:F1098=F8))"),1.0) -> 1 | AQ8: =Q8*L8 -> 5 | AR8: =IFERROR(__xludf.DUMMYFUNCTION("IF(and(REGEXMATCH(S8,""Vengence""),not(REGEXMATCH(S8, ""Protective Markings""))),AQ8,AQ8 * 6 / iferror(R8-1,6))"),10.0) -> 10 | AS8: =0 + if(P8="2d6",7,if(P8="d6",3.5,if(P8="d3",1.5,if(P8="2x2",4,if(P8="2x3",6,P8))))) -> 5 | AT8: =AS8*L8 -> 5 | AU8: =IFERROR(__xludf.DUMMYFUNCTION("IF(REGEXMATCH(S8,""<b>Poison</b>""),1+((1/(7-N8))/3),1)"),1.0) -> 1 | AV8: =IFERROR(__xludf.DUMMYFUNCTION("IF(REGEXMATCH(S8,""Vengence""),(7 - R8) / 3,0)"),0.0) -> 0 | AW8: =AV8 + (AT8*(7-N8)/6)*AU8 -> 3.3333333 | AX8: =AR8+(AW8*1.5) -> 15 | AY8: =IFERROR(__xludf.DUMMYFUNCTION("if(regexmatch(G8,""Mage|War Machine""),true,false)"),FALSE) -> FALSE
A9: 03_2A_2 | B9: Grave Beast | C9: =concatenate(E9," ",B9) -> Boneborn Grave Beast | D9: TRUE | E9: Boneborn | F9: Bonegiant | G9: Monster | H9: 5 | I9: 2 | L9: 1 | M9: 1 | N9: 4 | O9: - | P9: 4 | Q9: 7 | R9: 5 | S9: <b>Unstable</b> - Instead of rolling to flee, lose 1 extra wound <b>Revenants</b> - After combat, add a new wound for each enemy that died. Limited to the starting size. <b>Terrifying</b> - At the start of each round of combat, all enemy units in combat with it must roll to flee. If they flee out of combat, no combat takes place. | T9: 7 | Z9: 2 | AA9: 2 | AB9: 2 | AE9: #000000 | AF9: #000000 | AG9: #000000 | AH9: #000000 | AI9: #2b9800 | AJ9: #000000 | AK9: {=INDEX(Factions!C:C, MATCH(E9, Factions!B:B, 0))} -> #e0e0d3 | AL9: {=INDEX(Factions!D:D, MATCH(E9, Factions!B:B, 0))} -> #4d4d4d | AM9: {=INDEX(Factions!E:E, MATCH(E9, Factions!B:B, 0))} -> #000000 | AN9: {=INDEX(Factions!F:F, MATCH(E9, Factions!B:B, 0))} -> #ffffff | AO9: {=concat(INDEX(Factions!G:G, MATCH(E9, Factions!B:B, 0)),".png")} -> skellies.png | AP9: =IFERROR(__xludf.DUMMYFUNCTION("MIN(FILTER(M9:M1098, F9:F1098=F9))"),1.0) -> 1 | AQ9: =Q9*L9 -> 7 | AR9: =IFERROR(__xludf.DUMMYFUNCTION("IF(and(REGEXMATCH(S9,""Vengence""),not(REGEXMATCH(S9, ""Protective Markings""))),AQ9,AQ9 * 6 / iferror(R9-1,6))"),10.5) -> 10.5 | AS9: =0 + if(P9="2d6",7,if(P9="d6",3.5,if(P9="d3",1.5,if(P9="2x2",4,if(P9="2x3",6,P9))))) -> 4 | AT9: =AS9*L9 -> 4 | AU9: =IFERROR(__xludf.DUMMYFUNCTION("IF(REGEXMATCH(S9,""<b>Poison</b>""),1+((1/(7-N9))/3),1)"),1.0) -> 1 | AV9: =IFERROR(__xludf.DUMMYFUNCTION("IF(REGEXMATCH(S9,""Vengence""),(7 - R9) / 3,0)"),0.0) -> 0 | AW9: =AV9 + (AT9*(7-N9)/6)*AU9 -> 2 | AX9: =AR9+(AW9*1.5) -> 13.5 | AY9: =IFERROR(__xludf.DUMMYFUNCTION("if(regexmatch(G9,""Mage|War Machine""),true,false)"),FALSE) -> FALSE
A10: 03_2A_3 | B10: Skullclops | C10: =concatenate(E10," ",B10) -> Boneborn Skullclops | D10: TRUE | E10: Boneborn | F10: Bonegiant | G10: Monster | H10: 5 | I10: 2 | L10: 1 | M10: 1 | N10: 3 | O10: 3 | P10: 4 | Q10: 5 | R10: 5 | S10: <b>Unstable</b> - Instead of rolling to flee, lose 1 extra wound <b>Rock Lobber</b> - Ranged Weapon - Range 4, AP -2, Multiwound 3. | T10: 4 | Z10: 2 | AA10: 2 | AE10: #000000 | AF10: #2b9800 | AG10: #3467FF | AH10: #000000 | AI10: #2b9800 | AJ10: #000000 | AK10: {=INDEX(Factions!C:C, MATCH(E10, Factions!B:B, 0))} -> #e0e0d3 | AL10: {=INDEX(Factions!D:D, MATCH(E10, Factions!B:B, 0))} -> #4d4d4d | AM10: {=INDEX(Factions!E:E, MATCH(E10, Factions!B:B, 0))} -> #000000 | AN10: {=INDEX(Factions!F:F, MATCH(E10, Factions!B:B, 0))} -> #ffffff | AO10: {=concat(INDEX(Factions!G:G, MATCH(E10, Factions!B:B, 0)),".png")} -> skellies.png | AP10: =IFERROR(__xludf.DUMMYFUNCTION("MIN(FILTER(M10:M1098, F10:F1098=F10))"),1.0) -> 1 | AQ10: =Q10*L10 -> 5 | AR10: =IFERROR(__xludf.DUMMYFUNCTION("IF(and(REGEXMATCH(S10,""Vengence""),not(REGEXMATCH(S10, ""Protective Markings""))),AQ10,AQ10 * 6 / iferror(R10-1,6))"),7.5) -> 7.5 | AS10: =0 + if(P10="2d6",7,if(P10="d6",3.5,if(P10="d3",1.5,if(P10="2x2",4,if(P10="2x3",6,P10))))) -> 4 | AT10: =AS10*L10 -> 4 | AU10: =IFERROR(__xludf.DUMMYFUNCTION("IF(REGEXMATCH(S10,""<b>Poison</b>""),1+((1/(7-N10))/3),1)"),1.0) -> 1 | AV10: =IFERROR(__xludf.DUMMYFUNCTION("IF(REGEXMATCH(S10,""Vengence""),(7 - R10) / 3,0)"),0.0) -> 0 | AW10: =AV10 + (AT10*(7-N10)/6)*AU10 -> 2.6666667 | AX10: =AR10+(AW10*1.5) -> 11.5 | AY10: =IFERROR(__xludf.DUMMYFUNCTION("if(regexmatch(G10,""Mage|War Machine""),true,false)"),FALSE) -> FALSE
A11: 03_2B_2 | B11: Terrormancers | C11: =concatenate(E11," ",B11) -> Boneborn Terrormancers | D11: TRUE | E11: Boneborn | F11: Liches | G11: Attack Mage | H11: 6 | I11: 2 | L11: 3 | M11: 1 | N11: 4 | O11: 4 | P11: 2 | Q11: 2 | R11: 5 | S11: <b>Unstable</b> - Instead of rolling to flee, lose 1 extra wound <b>Bone Spurs</b> - Ranged weapon. Can target any unit adjacent to a friendly Boneborn unit. Can fire into combat. Units wounded by this attack must immediately roll to flee. | T11: 3 | W11: 2 | AE11: #000000 | AF11: #000000 | AG11: #2b9800 | AH11: #000000 | AI11: #000000 | AJ11: #000000 | AK11: {=INDEX(Factions!C:C, MATCH(E11, Factions!B:B, 0))} -> #e0e0d3 | AL11: {=INDEX(Factions!D:D, MATCH(E11, Factions!B:B, 0))} -> #4d4d4d | AM11: {=INDEX(Factions!E:E, MATCH(E11, Factions!B:B, 0))} -> #000000 | AN11: {=INDEX(Factions!F:F, MATCH(E11, Factions!B:B, 0))} -> #ffffff | AO11: {=concat(INDEX(Factions!G:G, MATCH(E11, Factions!B:B, 0)),".png")} -> skellies.png | AP11: =IFERROR(__xludf.DUMMYFUNCTION("MIN(FILTER(M11:M1098, F11:F1098=F11))"),1.0) -> 1 | AQ11: =Q11*L11 -> 6 | AR11: =IFERROR(__xludf.DUMMYFUNCTION("IF(and(REGEXMATCH(S11,""Vengence""),not(REGEXMATCH(S11, ""Protective Markings""))),AQ11,AQ11 * 6 / iferror(R11-1,6))"),9.0) -> 9 | AS11: =0 + if(P11="2d6",7,if(P11="d6",3.5,if(P11="d3",1.5,if(P11="2x2",4,if(P11="2x3",6,P11))))) -> 2 | AT11: =AS11*L11 -> 6 | AU11: =IFERROR(__xludf.DUMMYFUNCTION("IF(REGEXMATCH(S11,""<b>Poison</b>""),1+((1/(7-N11))/3),1)"),1.0) -> 1 | AV11: =IFERROR(__xludf.DUMMYFUNCTION("IF(REGEXMATCH(S11,""Vengence""),(7 - R11) / 3,0)"),0.0) -> 0 | AW11: =AV11 + (AT11*(7-N11)/6)*AU11 -> 3 | AX11: =AR11+(AW11*1.5) -> 13.5 | AY11: =IFERROR(__xludf.DUMMYFUNCTION("if(regexmatch(G11,""Mage|War Machine""),true,false)"),TRUE) -> TRUE
A12: 03_2B_3 | B12: Blood Mages | C12: =concatenate(E12," ",B12) -> Boneborn Blood Mages | D12: TRUE | E12: Boneborn | F12: Liches | G12: Attack Infantry | H12: 6 | I12: 2 | L12: 3 | M12: 1 | N12: 3 | O12: - | P12: 3 | Q12: 2 | R12: 5 | S12: <b>Unstable</b> - Instead of rolling to flee, lose 1 extra wound <b>Blood Rites</b> - After combat, roll an extra attack for each wound this unit dealt in combat. This can damage a unit that has fled from it. | T12: 6 | W12: 2 | AE12: #000000 | AF12: #2b9800 | AG12: #000000 | AH12: #2b9800 | AI12: #000000 | AJ12: #000000 | AK12: {=INDEX(Factions!C:C, MATCH(E12, Factions!B:B, 0))} -> #e0e0d3 | AL12: {=INDEX(Factions!D:D, MATCH(E12, Factions!B:B, 0))} -> #4d4d4d | AM12: {=INDEX(Factions!E:E, MATCH(E12, Factions!B:B, 0))} -> #000000 | AN12: {=INDEX(Factions!F:F, MATCH(E12, Factions!B:B, 0))} -> #ffffff | AO12: {=concat(INDEX(Factions!G:G, MATCH(E12, Factions!B:B, 0)),".png")} -> skellies.png | AP12: =IFERROR(__xludf.DUMMYFUNCTION("MIN(FILTER(M12:M1098, F12:F1098=F12))"),1.0) -> 1 | AQ12: =Q12*L12 -> 6 | AR12: =IFERROR(__xludf.DUMMYFUNCTION("IF(and(REGEXMATCH(S12,""Vengence""),not(REGEXMATCH(S12, ""Protective Markings""))),AQ12,AQ12 * 6 / iferror(R12-1,6))"),9.0) -> 9 | AS12: =0 + if(P12="2d6",7,if(P12="d6",3.5,if(P12="d3",1.5,if(P12="2x2",4,if(P12="2x3",6,P12))))) -> 3 | AT12: =AS12*L12 -> 9 | AU12: =IFERROR(__xludf.DUMMYFUNCTION("IF(REGEXMATCH(S12,""<b>Poison</b>""),1+((1/(7-N12))/3),1)"),1.0) -> 1 | AV12: =IFERROR(__xludf.DUMMYFUNCTION("IF(REGEXMATCH(S12,""Vengence""),(7 - R12) / 3,0)"),0.0) -> 0 | AW12: =AV12 + (AT12*(7-N12)/6)*AU12 -> 6 | AX12: =AR12+(AW12*1.5) -> 18 | AY12: =IFERROR(__xludf.DUMMYFUNCTION("if(regexmatch(G12,""Mage|War Machine""),true,false)"),FALSE) -> FALSE
A13: 03_2C_1 | B13: Wall of Flesh | C13: =concatenate(E13," ",B13) -> Boneborn Wall of Flesh | D13: TRUE | E13: Boneborn | F13: Zombies | G13: Heavy Infantry | H13: 6 | I13: 2 | L13: 6 | M13: 1 | N13: 5 | O13: - | P13: 1 | Q13: 2 | R13: 5 | S13: <b>Unstable</b> - Instead of rolling to flee, lose 1 extra wound <b>Spongey 2</b> - Ignore 2 damage every round of combat or when hit by a ranged attack. <b>Slow</b> - Can't hustle | T13: 7.25 | Y13: 2 | Z13: 2 | AA13: 2 | AC13: 2 | AE13: #000000 | AF13: #cc0000 | AG13: #000000 | AH13: #000000 | AI13: #2b9800 | AJ13: #000000 | AK13: {=INDEX(Factions!C:C, MATCH(E13, Factions!B:B, 0))} -> #e0e0d3 | AL13: {=INDEX(Factions!D:D, MATCH(E13, Factions!B:B, 0))} -> #4d4d4d | AM13: {=INDEX(Factions!E:E, MATCH(E13, Factions!B:B, 0))} -> #000000 | AN13: {=INDEX(Factions!F:F, MATCH(E13, Factions!B:B, 0))} -> #ffffff | AO13: {=concat(INDEX(Factions!G:G, MATCH(E13, Factions!B:B, 0)),".png")} -> skellies.png | AP13: =IFERROR(__xludf.DUMMYFUNCTION("MIN(FILTER(M13:M1098, F13:F1098=F13))"),1.0) -> 1 | AQ13: =Q13*L13 -> 12 | AR13: =IFERROR(__xludf.DUMMYFUNCTION("IF(and(REGEXMATCH(S13,""Vengence""),not(REGEXMATCH(S13, ""Protective Markings""))),AQ13,AQ13 * 6 / iferror(R13-1,6))"),18.0) -> 18 | AS13: =0 + if(P13="2d6",7,if(P13="d6",3.5,if(P13="d3",1.5,if(P13="2x2",4,if(P13="2x3",6,P13))))) -> 1 | AT13: =AS13*L13 -> 6 | AU13: =IFERROR(__xludf.DUMMYFUNCTION("IF(REGEXMATCH(S13,""<b>Poison</b>""),1+((1/(7-N13))/3),1)"),1.0) -> 1 | AV13: =IFERROR(__xludf.DUMMYFUNCTION("IF(REGEXMATCH(S13,""Vengence""),(7 - R13) / 3,0)"),0.0) -> 0 | AW13: =AV13 + (AT13*(7-N13)/6)*AU13 -> 2 | AX13: =AR13+(AW13*1.5) -> 21 | AY13: =IFERROR(__xludf.DUMMYFUNCTION("if(regexmatch(G13,""Mage|War Machine""),true,false)"),FALSE) -> FALSE
A14: 03_2C_3 | B14: Rotting Dead | C14: =concatenate(E14," ",B14) -> Boneborn Rotting Dead | D14: TRUE | E14: Boneborn | F14: Zombies | G14: Unique | H14: 6 | I14: 2 | L14: 6 | M14: 1 | N14: 5 | O14: - | P14: 1 | Q14: 2 | R14: 5 | S14: <b>Unstable</b> - Instead of rolling to flee, lose 1 extra wound <b>Poison</b> - 6s to hit can't be saved <b>Plague</b> - At the end of each player's turn, units adjacent to this unit suffer a wound on a 4+ with no armour saves allowed. Does not affect Boneborn units. | T14: 6 | Y14: 2 | Z14: 2 | AA14: 2 | AB14: 2 | AC14: 2 | AE14: #000000 | AF14: #cc0000 | AG14: #000000 | AH14: #000000 | AI14: #2b9800 | AJ14: #000000 | AK14: {=INDEX(Factions!C:C, MATCH(E14, Factions!B:B, 0))} -> #e0e0d3 | AL14: {=INDEX(Factions!D:D, MATCH(E14, Factions!B:B, 0))} -> #4d4d4d | AM14: {=INDEX(Factions!E:E, MATCH(E14, Factions!B:B, 0))} -> #000000 | AN14: {=INDEX(Factions!F:F, MATCH(E14, Factions!B:B, 0))} -> #ffffff | AO14: {=concat(INDEX(Factions!G:G, MATCH(E14, Factions!B:B, 0)),".png")} -> skellies.png | AP14: =IFERROR(__xludf.DUMMYFUNCTION("MIN(FILTER(M14:M1098, F14:F1098=F14))"),1.0) -> 1 | AQ14: =Q14*L14 -> 12 | AR14: =IFERROR(__xludf.DUMMYFUNCTION("IF(and(REGEXMATCH(S14,""Vengence""),not(REGEXMATCH(S14, ""Protective Markings""))),AQ14,AQ14 * 6 / iferror(R14-1,6))"),18.0) -> 18 | AS14: =0 + if(P14="2d6",7,if(P14="d6",3.5,if(P14="d3",1.5,if(P14="2x2",4,if(P14="2x3",6,P14))))) -> 1 | AT14: =AS14*L14 -> 6 | AU14: =IFERROR(__xludf.DUMMYFUNCTION("IF(REGEXMATCH(S14,""<b>Poison</b>""),1+((1/(7-N14))/3),1)"),1.1666666666666667) -> 1.1666667 | AV14: =IFERROR(__xludf.DUMMYFUNCTION("IF(REGEXMATCH(S14,""Vengence""),(7 - R14) / 3,0)"),0.0) -> 0 | AW14: =AV14 + (AT14*(7-N14)/6)*AU14 -> 2.3333333 | AX14: =AR14+(AW14*1.5) -> 21.5 | AY14: =IFERROR(__xludf.DUMMYFUNCTION("if(regexmatch(G14,""Mage|War Machine""),true,false)"),FALSE) -> FALSE
A15: 03_2B_1 | B15: Necromancers | C15: =concatenate(E15," ",B15) -> Boneborn Necromancers | D15: TRUE | E15: Boneborn | F15: Liches | G15: Support Mage | H15: 6 | I15: 2 | L15: 3 | M15: 1 | N15: 2 | O15: - | P15: 1 | Q15: 2 | R15: 6 | S15: <b>Unstable</b> - Instead of rolling to flee, lose 1 extra wound <b>Raise the Dead 1</b> - Free action: Choose an undead unit and heal 1 wound per Necromancer. This can resurrect models. Limited to the starting number of units/wounds. <b>Stabalizer</b> - Units affected by Raise the Dead do not lose wounds due to unstable this turn. | T15: 3 | W15: 2 | AE15: #000000 | AF15: #3467FF | AG15: #000000 | AH15: #cc0000 | AI15: #000000 | AJ15: #cc0000 | AK15: {=INDEX(Factions!C:C, MATCH(E15, Factions!B:B, 0))} -> #e0e0d3 | AL15: {=INDEX(Factions!D:D, MATCH(E15, Factions!B:B, 0))} -> #4d4d4d | AM15: {=INDEX(Factions!E:E, MATCH(E15, Factions!B:B, 0))} -> #000000 | AN15: {=INDEX(Factions!F:F, MATCH(E15, Factions!B:B, 0))} -> #ffffff | AO15: {=concat(INDEX(Factions!G:G, MATCH(E15, Factions!B:B, 0)),".png")} -> skellies.png | AP15: =IFERROR(__xludf.DUMMYFUNCTION("MIN(FILTER(M15:M1098, F15:F1098=F15))"),1.0) -> 1 | AQ15: =Q15*L15 -> 6 | AR15: =IFERROR(__xludf.DUMMYFUNCTION("IF(and(REGEXMATCH(S15,""Vengence""),not(REGEXMATCH(S15, ""Protective Markings""))),AQ15,AQ15 * 6 / iferror(R15-1,6))"),7.2) -> 7.2 | AS15: =0 + if(P15="2d6",7,if(P15="d6",3.5,if(P15="d3",1.5,if(P15="2x2",4,if(P15="2x3",6,P15))))) -> 1 | AT15: =AS15*L15 -> 3 | AU15: =IFERROR(__xludf.DUMMYFUNCTION("IF(REGEXMATCH(S15,""<b>Poison</b>""),1+((1/(7-N15))/3),1)"),1.0) -> 1 | AV15: =IFERROR(__xludf.DUMMYFUNCTION("IF(REGEXMATCH(S15,""Vengence""),(7 - R15) / 3,0)"),0.0) -> 0 | AW15: =AV15 + (AT15*(7-N15)/6)*AU15 -> 2.5 | AX15: =AR15+(AW15*1.5) -> 10.95 | AY15: =IFERROR(__xludf.DUMMYFUNCTION("if(regexmatch(G15,""Mage|War Machine""),true,false)"),TRUE) -> TRUE
A16: 03_2C_2 | B16: Ghouls | C16: =concatenate(E16," ",B16) -> Boneborn Ghouls | D16: TRUE | E16: Boneborn | F16: Zombies | G16: Fast Infantry | H16: 6 | I16: 2 | L16: 6 | M16: 1 | N16: 4 | O16: - | P16: 1 | Q16: 2 | R16: 6 | S16: <b>Unstable</b> - Instead of rolling to flee, lose 1 extra wound <b>Fresh Revenants</b> - After combat, add a new ghoul with full health for each enemy that died. Limited to the starting size. <b>Fast</b> - Rolls two hustle die, so it can travel up to two extra squares. | T16: 6.75 | Z16: 2 | AA16: 2 | AB16: 2 | AE16: #000000 | AF16: #000000 | AG16: #000000 | AH16: #000000 | AI16: #2b9800 | AJ16: #cc0000 | AK16: {=INDEX(Factions!C:C, MATCH(E16, Factions!B:B, 0))} -> #e0e0d3 | AL16: {=INDEX(Factions!D:D, MATCH(E16, Factions!B:B, 0))} -> #4d4d4d | AM16: {=INDEX(Factions!E:E, MATCH(E16, Factions!B:B, 0))} -> #000000 | AN16: {=INDEX(Factions!F:F, MATCH(E16, Factions!B:B, 0))} -> #ffffff | AO16: {=concat(INDEX(Factions!G:G, MATCH(E16, Factions!B:B, 0)),".png")} -> skellies.png | AP16: =IFERROR(__xludf.DUMMYFUNCTION("MIN(FILTER(M16:M1098, F16:F1098=F16))"),1.0) -> 1 | AQ16: =Q16*L16 -> 12 | AR16: =IFERROR(__xludf.DUMMYFUNCTION("IF(and(REGEXMATCH(S16,""Vengence""),not(REGEXMATCH(S16, ""Protective Markings""))),AQ16,AQ16 * 6 / iferror(R16-1,6))"),14.4) -> 14.4 | AS16: =0 + if(P16="2d6",7,if(P16="d6",3.5,if(P16="d3",1.5,if(P16="2x2",4,if(P16="2x3",6,P16))))) -> 1 | AT16: =AS16*L16 -> 6 | AU16: =IFERROR(__xludf.DUMMYFUNCTION("IF(REGEXMATCH(S16,""<b>Poison</b>""),1+((1/(7-N16))/3),1)"),1.0) -> 1 | AV16: =IFERROR(__xludf.DUMMYFUNCTION("IF(REGEXMATCH(S16,""Vengence""),(7 - R16) / 3,0)"),0.0) -> 0 | AW16: =AV16 + (AT16*(7-N16)/6)*AU16 -> 3 | AX16: =AR16+(AW16*1.5) -> 18.9 | AY16: =IFERROR(__xludf.DUMMYFUNCTION("if(regexmatch(G16,""Mage|War Machine""),true,false)"),FALSE) -> FALSE
A17: 06_1_4 | B17: Supplicants | C17: =concatenate(E17," ",B17) -> Coppersand Supplicants | D17: TRUE | E17: Coppersand | F17: Mechanics | G17: Unique | H17: 6 | I17: 1 | J17: 2 | L17: 5 | M17: 1 | N17: 5 | O17: - | P17: 1 | Q17: 1 | R17: - | S17: <b>Mechanics</b> - At the start of your turn, heal 1 wound on an adjacent construct. <b>Meatshields</b> - When an adjacent friendly construct is attacked, before rolling to block, you may redirect all of the attacks to this unit. Any wounds taken count towards combat resolution. <b>Unprotected</b> - Reveal this unit when an attack hits it, rather than using the default block. | T17: 2 | Y17: 1 | AC17: 1 | AE17: #000000 | AF17: #cc0000 | AG17: #000000 | AH17: #000000 | AI17: #000000 | AJ17: #cc0000 | AK17: {=INDEX(Factions!C:C, MATCH(E17, Factions!B:B, 0))} -> #ffb317 | AL17: {=INDEX(Factions!D:D, MATCH(E17, Factions!B:B, 0))} -> #cf6c23 | AM17: {=INDEX(Factions!E:E, MATCH(E17, Factions!B:B, 0))} -> #000000 | AN17: {=INDEX(Factions!F:F, MATCH(E17, Factions!B:B, 0))} -> #ffffff | AO17: {=concat(INDEX(Factions!G:G, MATCH(E17, Factions!B:B, 0)),".png")} -> gremlins.png | AP17: =IFERROR(__xludf.DUMMYFUNCTION("MIN(FILTER(M17:M1098, F17:F1098=F17))"),1.0) -> 1 | AQ17: =Q17*L17 -> 5 | AR17: =IFERROR(__xludf.DUMMYFUNCTION("IF(and(REGEXMATCH(S17,""Vengence""),not(REGEXMATCH(S17, ""Protective Markings""))),AQ17,AQ17 * 6 / iferror(R17-1,6))"),5.0) -> 5 | AS17: =0 + if(P17="2d6",7,if(P17="d6",3.5,if(P17="d3",1.5,if(P17="2x2",4,if(P17="2x3",6,P17))))) -> 1 | AT17: =AS17*L17 -> 5 | AU17: =IFERROR(__xludf.DUMMYFUNCTION("IF(REGEXMATCH(S17,""<b>Poison</b>""),1+((1/(7-N17))/3),1)"),1.0) -> 1 | AV17: =IFERROR(__xludf.DUMMYFUNCTION("IF(REGEXMATCH(S17,""Vengence""),(7 - R17) / 3,0)"),0.0) -> 0 | AW17: =AV17 + (AT17*(7-N17)/6)*AU17 -> 1.6666667 | AX17: =AR17+(AW17*1.5) -> 7.5 | AY17: =IFERROR(__xludf.DUMMYFUNCTION("if(regexmatch(G17,""Mage|War Machine""),true,false)"),FALSE) -> FALSE
A18: 06_1_1 | B18: Warriors | C18: =concatenate(E18," ",B18) -> Coppersand Warriors | D18: TRUE | E18: Coppersand | F18: Mechanics | G18: Warriors | H18: 6 | I18: 1 | J18: 2 | L18: 5 | M18: 1 | N18: 4 | O18: 6 | P18: 1 | Q18: 1 | R18: 5 | S18: <b>Mechanics</b> - At the start of your turn, heal 1 wound on an adjacent construct. | T18: 3.5 | Y18: 1 | Z18: 1 | AA18: 1 | AB18: 1 | AC18: 1 | AD18: 1 | AE18: #000000 | AF18: #000000 | AG18: #000000 | AH18: #000000 | AI18: #000000 | AJ18: #000000 | AK18: {=INDEX(Factions!C:C, MATCH(E18, Factions!B:B, 0))} -> #ffb317 | AL18: {=INDEX(Factions!D:D, MATCH(E18, Factions!B:B, 0))} -> #cf6c23 | AM18: {=INDEX(Factions!E:E, MATCH(E18, Factions!B:B, 0))} -> #000000 | AN18: {=INDEX(Factions!F:F, MATCH(E18, Factions!B:B, 0))} -> #ffffff | AO18: {=concat(INDEX(Factions!G:G, MATCH(E18, Factions!B:B, 0)),".png")} -> gremlins.png | AP18: =IFERROR(__xludf.DUMMYFUNCTION("MIN(FILTER(M18:M1098, F18:F1098=F18))"),1.0) -> 1 | AQ18: =Q18*L18 -> 5 | AR18: =IFERROR(__xludf.DUMMYFUNCTION("IF(and(REGEXMATCH(S18,""Vengence""),not(REGEXMATCH(S18, ""Protective Markings""))),AQ18,AQ18 * 6 / iferror(R18-1,6))"),7.5) -> 7.5 | AS18: =0 + if(P18="2d6",7,if(P18="d6",3.5,if(P18="d3",1.5,if(P18="2x2",4,if(P18="2x3",6,P18))))) -> 1 | AT18: =AS18*L18 -> 5 | AU18: =IFERROR(__xludf.DUMMYFUNCTION("IF(REGEXMATCH(S18,""<b>Poison</b>""),1+((1/(7-N18))/3),1)"),1.0) -> 1 | AV18: =IFERROR(__xludf.DUMMYFUNCTION("IF(REGEXMATCH(S18,""Vengence""),(7 - R18) / 3,0)"),0.0) -> 0 | AW18: =AV18 + (AT18*(7-N18)/6)*AU18 -> 2.5 | AX18: =AR18+(AW18*1.5) -> 11.25 | AY18: =IFERROR(__xludf.DUMMYFUNCTION("if(regexmatch(G18,""Mage|War Machine""),true,false)"),FALSE) -> FALSE
A19: 06_1_2 | B19: Gunners | C19: =concatenate(E19," ",B19) -> Coppersand Gunners | D19: TRUE | E19: Coppersand | F19: Mechanics | G19: Archers | H19: 6 | I19: 1 | J19: 2 | L19: 5 | M19: 1 | N19: 5 | O19: 4 | P19: 1 | Q19: 1 | R19: 6 | S19: <b>Mechanics</b> - At the start of your turn, heal 1 wound on an adjacent construct. | T19: 2.5 | Y19: 1 | Z19: 1 | AA19: 1 | AB19: 1 | AC19: 1 | AD19: 1 | AE19: #000000 | AF19: #cc0000 | AG19: #2b9800 | AH19: #000000 | AI19: #000000 | AJ19: #cc0000 | AK19: {=INDEX(Factions!C:C, MATCH(E19, Factions!B:B, 0))} -> #ffb317 | AL19: {=INDEX(Factions!D:D, MATCH(E19, Factions!B:B, 0))} -> #cf6c23 | AM19: {=INDEX(Factions!E:E, MATCH(E19, Factions!B:B, 0))} -> #000000 | AN19: {=INDEX(Factions!F:F, MATCH(E19, Factions!B:B, 0))} -> #ffffff | AO19: {=concat(INDEX(Factions!G:G, MATCH(E19, Factions!B:B, 0)),".png")} -> gremlins.png | AP19: =IFERROR(__xludf.DUMMYFUNCTION("MIN(FILTER(M19:M1098, F19:F1098=F19))"),1.0) -> 1 | AQ19: =Q19*L19 -> 5 | AR19: =IFERROR(__xludf.DUMMYFUNCTION("IF(and(REGEXMATCH(S19,""Vengence""),not(REGEXMATCH(S19, ""Protective Markings""))),AQ19,AQ19 * 6 / iferror(R19-1,6))"),6.0) -> 6 | AS19: =0 + if(P19="2d6",7,if(P19="d6",3.5,if(P19="d3",1.5,if(P19="2x2",4,if(P19="2x3",6,P19))))) -> 1 | AT19: =AS19*L19 -> 5 | AU19: =IFERROR(__xludf.DUMMYFUNCTION("IF(REGEXMATCH(S19,""<b>Poison</b>""),1+((1/(7-N19))/3),1)"),1.0) -> 1 | AV19: =IFERROR(__xludf.DUMMYFUNCTION("IF(REGEXMATCH(S19,""Vengence""),(7 - R19) / 3,0)"),0.0) -> 0 | AW19: =AV19 + (AT19*(7-N19)/6)*AU19 -> 1.6666667 | AX19: =AR19+(AW19*1.5) -> 8.5 | AY19: =IFERROR(__xludf.DUMMYFUNCTION("if(regexmatch(G19,""Mage|War Machine""),true,false)"),FALSE) -> FALSE
A20: 06_1_3 | B20: Sappers | C20: =concatenate(E20," ",B20) -> Coppersand Sappers | D20: TRUE | E20: Coppersand | F20: Mechanics | G20: Unique | H20: 6 | I20: 1 | J20: 2 | L20: 5 | M20: 1 | N20: 6 | O20: 5 | P20: 1 | Q20: 1 | R20: 6 | S20: <b>Mechanics</b> - At the start of your turn, heal 1 wound on an adjacent construct. <b>Entrench</b> - Units that move adjacent to this unit are disrupted. Each model in the unit takes a wound, hitting on that unit's block score. This affects friendly units as well. | T20: 2 | Y20: 1 | Z20: 1 | AA20: 1 | AB20: 1 | AC20: 1 | AD20: 1 | AE20: #000000 | AF20: #cc0000 | AG20: #2b9800 | AH20: #000000 | AI20: #000000 | AJ20: #cc0000 | AK20: {=INDEX(Factions!C:C, MATCH(E20, Factions!B:B, 0))} -> #ffb317 | AL20: {=INDEX(Factions!D:D, MATCH(E20, Factions!B:B, 0))} -> #cf6c23 | AM20: {=INDEX(Factions!E:E, MATCH(E20, Factions!B:B, 0))} -> #000000 | AN20: {=INDEX(Factions!F:F, MATCH(E20, Factions!B:B, 0))} -> #ffffff | AO20: {=concat(INDEX(Factions!G:G, MATCH(E20, Factions!B:B, 0)),".png")} -> gremlins.png | AP20: =IFERROR(__xludf.DUMMYFUNCTION("MIN(FILTER(M20:M1098, F20:F1098=F20))"),1.0) -> 1 | AQ20: =Q20*L20 -> 5 | AR20: =IFERROR(__xludf.DUMMYFUNCTION("IF(and(REGEXMATCH(S20,""Vengence""),not(REGEXMATCH(S20, ""Protective Markings""))),AQ20,AQ20 * 6 / iferror(R20-1,6))"),6.0) -> 6 | AS20: =0 + if(P20="2d6",7,if(P20="d6",3.5,if(P20="d3",1.5,if(P20="2x2",4,if(P20="2x3",6,P20))))) -> 1 | AT20: =AS20*L20 -> 5 | AU20: =IFERROR(__xludf.DUMMYFUNCTION("IF(REGEXMATCH(S20,""<b>Poison</b>""),1+((1/(7-N20))/3),1)"),1.0) -> 1 | AV20: =IFERROR(__xludf.DUMMYFUNCTION("IF(REGEXMATCH(S20,""Vengence""),(7 - R20) / 3,0)"),0.0) -> 0 | AW20: =AV20 + (AT20*(7-N20)/6)*AU20 -> 0.83333333 | AX20: =AR20+(AW20*1.5) -> 7.25 | AY20: =IFERROR(__xludf.DUMMYFUNCTION("if(regexmatch(G20,""Mage|War Machine""),true,false)"),FALSE) -> FALSE
A21: 06_1_5 | B21: Artificers | C21: =concatenate(E21," ",B21) -> Coppersand Artificers | D21: TRUE | E21: Coppersand | F21: Mechanics | G21: Infantry | H21: 6 | I21: 1 | J21: 3 | L21: 5 | M21: 1 | N21: 4 | O21: 5 | P21: 1 | Q21: 1 | R21: 5 | S21: <b>Mechanics</b> - At the start of your turn, heal 1 wound on an adjacent construct <b>Prepared Equipment</b> - Equip this unit with one piece of free uncommon equipment, or two pieces of common equipment. <b>Equippable</b> - Able to equip uncommon equipment | T21: 4.5 | U21: <b>AP 2</b> | Y21: 2 | Z21: 2 | AA21: 2 | AB21: 2 | AC21: 2 | AD21: 2 | AE21: #000000 | AF21: #000000 | AG21: #2b9800 | AH21: #000000 | AI21: #000000 | AJ21: #000000 | AK21: {=INDEX(Factions!C:C, MATCH(E21, Factions!B:B, 0))} -> #ffb317 | AL21: {=INDEX(Factions!D:D, MATCH(E21, Factions!B:B, 0))} -> #cf6c23 | AM21: {=INDEX(Factions!E:E, MATCH(E21, Factions!B:B, 0))} -> #000000 | AN21: {=INDEX(Factions!F:F, MATCH(E21, Factions!B:B, 0))} -> #ffffff | AO21: {=concat(INDEX(Factions!G:G, MATCH(E21, Factions!B:B, 0)),".png")} -> gremlins.png | AP21: =IFERROR(__xludf.DUMMYFUNCTION("MIN(FILTER(M21:M1098, F21:F1098=F21))"),1.0) -> 1 | AQ21: =Q21*L21 -> 5 | AR21: =IFERROR(__xludf.DUMMYFUNCTION("IF(and(REGEXMATCH(S21,""Vengence""),not(REGEXMATCH(S21, ""Protective Markings""))),AQ21,AQ21 * 6 / iferror(R21-1,6))"),7.5) -> 7.5 | AS21: =0 + if(P21="2d6",7,if(P21="d6",3.5,if(P21="d3",1.5,if(P21="2x2",4,if(P21="2x3",6,P21))))) -> 1 | AT21: =AS21*L21 -> 5 | AU21: =IFERROR(__xludf.DUMMYFUNCTION("IF(REGEXMATCH(S21,""<b>Poison</b>""),1+((1/(7-N21))/3),1)"),1.0) -> 1 | AV21: =IFERROR(__xludf.DUMMYFUNCTION("IF(REGEXMATCH(S21,""Vengence""),(7 - R21) / 3,0)"),0.0) -> 0 | AW21: =AV21 + (AT21*(7-N21)/6)*AU21 -> 2.5 | AX21: =AR21+(AW21*1.5) -> 11.25 | AY21: =IFERROR(__xludf.DUMMYFUNCTION("if(regexmatch(G21,""Mage|War Machine""),true,false)"),FALSE) -> FALSE
A22: 06_1_6 | B22: Snipers | C22: =concatenate(E22," ",B22) -> Coppersand Snipers | D22: TRUE | E22: Coppersand | F22: Mechanics | G22: Archers | H22: 6 | I22: 1 | J22: 3 | L22: 5 | M22: 1 | N22: 5 | O22: 4 | P22: 1 | Q22: 1 | R22: 5 | S22: <b>Mechanics</b> - At the start of your turn, heal 1 wound on an adjacent construct. <b>Long Range</b> - This unit's ranged weapons gain 1 range. | T22: 2.5 | Y22: 1 | Z22: 1 | AA22: 1 | AB22: 1 | AC22: 1 | AD22: 1 | AE22: #000000 | AF22: #cc0000 | AG22: #2b9800 | AH22: #2b9800 | AI22: #cc0000 | AJ22: #000000 | AK22: {=INDEX(Factions!C:C, MATCH(E22, Factions!B:B, 0))} -> #ffb317 | AL22: {=INDEX(Factions!D:D, MATCH(E22, Factions!B:B, 0))} -> #cf6c23 | AM22: {=INDEX(Factions!E:E, MATCH(E22, Factions!B:B, 0))} -> #000000 | AN22: {=INDEX(Factions!F:F, MATCH(E22, Factions!B:B, 0))} -> #ffffff | AO22: {=concat(INDEX(Factions!G:G, MATCH(E22, Factions!B:B, 0)),".png")} -> gremlins.png | AP22: =IFERROR(__xludf.DUMMYFUNCTION("MIN(FILTER(M22:M1098, F22:F1098=F22))"),1.0) -> 1 | AQ22: =Q22*L22 -> 5 | AR22: =IFERROR(__xludf.DUMMYFUNCTION("IF(and(REGEXMATCH(S22,""Vengence""),not(REGEXMATCH(S22, ""Protective Markings""))),AQ22,AQ22 * 6 / iferror(R22-1,6))"),7.5) -> 7.5 | AS22: =0 + if(P22="2d6",7,if(P22="d6",3.5,if(P22="d3",1.5,if(P22="2x2",4,if(P22="2x3",6,P22))))) -> 1 | AT22: =AS22*L22 -> 5 | AU22: =IFERROR(__xludf.DUMMYFUNCTION("IF(REGEXMATCH(S22,""<b>Poison</b>""),1+((1/(7-N22))/3),1)"),1.0) -> 1 | AV22: =IFERROR(__xludf.DUMMYFUNCTION("IF(REGEXMATCH(S22,""Vengence""),(7 - R22) / 3,0)"),0.0) -> 0 | AW22: =AV22 + (AT22*(7-N22)/6)*AU22 -> 1.6666667 | AX22: =AR22+(AW22*1.5) -> 10 | AY22: =IFERROR(__xludf.DUMMYFUNCTION("if(regexmatch(G22,""Mage|War Machine""),true,false)"),FALSE) -> FALSE
A23: 06_2B_3 | B23: Warcrane | C23: =concatenate(E23," ",B23) -> Coppersand Warcrane | D23: TRUE | E23: Coppersand | F23: Colossus | G23: Monster | H23: 5 | I23: 2 | L23: 1 | M23: 1 | N23: 5 | O23: - | P23: 5 | Q23: 7 | R23: 3 | S23: <b>Construct</b> - Immune to fear checks while adjacent to a mechanic. Dies if it flees. <b>Lift and Shift</b> - Action: Rotate an adjacent unit 90 degrees around this unit. You may rotate this unit in the same direction. May not move units off the board. The unit counts as having moved for the purpose of rules like Entrenched. | T23: 6 | AE23: #000000 | AF23: #cc0000 | AG23: #000000 | AH23: #2b9800 | AI23: #2b9800 | AJ23: #3467FF | AK23: {=INDEX(Factions!C:C, MATCH(E23, Factions!B:B, 0))} -> #ffb317 | AL23: {=INDEX(Factions!D:D, MATCH(E23, Factions!B:B, 0))} -> #cf6c23 | AM23: {=INDEX(Factions!E:E, MATCH(E23, Factions!B:B, 0))} -> #000000 | AN23: {=INDEX(Factions!F:F, MATCH(E23, Factions!B:B, 0))} -> #ffffff | AO23: {=concat(INDEX(Factions!G:G, MATCH(E23, Factions!B:B, 0)),".png")} -> gremlins.png | AP23: =IFERROR(__xludf.DUMMYFUNCTION("MIN(FILTER(M23:M1098, F23:F1098=F23))"),1.0) -> 1 | AQ23: =Q23*L23 -> 7 | AR23: =IFERROR(__xludf.DUMMYFUNCTION("IF(and(REGEXMATCH(S23,""Vengence""),not(REGEXMATCH(S23, ""Protective Markings""))),AQ23,AQ23 * 6 / iferror(R23-1,6))"),21.0) -> 21 | AS23: =0 + if(P23="2d6",7,if(P23="d6",3.5,if(P23="d3",1.5,if(P23="2x2",4,if(P23="2x3",6,P23))))) -> 5 | AT23: =AS23*L23 -> 5 | AU23: =IFERROR(__xludf.DUMMYFUNCTION("IF(REGEXMATCH(S23,""<b>Poison</b>""),1+((1/(7-N23))/3),1)"),1.0) -> 1 | AV23: =IFERROR(__xludf.DUMMYFUNCTION("IF(REGEXMATCH(S23,""Vengence""),(7 - R23) / 3,0)"),0.0) -> 0 | AW23: =AV23 + (AT23*(7-N23)/6)*AU23 -> 1.6666667 | AX23: =AR23+(AW23*1.5) -> 23.5 | AY23: =IFERROR(__xludf.DUMMYFUNCTION("if(regexmatch(G23,""Mage|War Machine""),true,false)"),FALSE) -> FALSE
A24: 06_2B_1 | B24: Juggernaut | C24: =concatenate(E24," ",B24) -> Coppersand Juggernaut | D24: TRUE | E24: Coppersand | F24: Colossus | G24: Monster | H24: 5 | I24: 2 | L24: 1 | M24: 2 | N24: 3 | O24: - | P24: 5 | Q24: 5 | R24: 4 | S24: <b>Construct</b> - Immune to fear checks while adjacent to a mechanic. Dies if it flees. <b>Trample</b> - Action: Move forward 1. If there is a model in that space, it attempts to move backwards 1 unless it is blocked. Roll an attack against each model in the unit, hitting on 6+ or 4+ if the unit was blocked. These do not count for combat resolution. Can be used to move out of combat. | T24: 6 | Y24: 2 | Z24: 2 | AA24: 2 | AB24: 2 | AE24: #2b9800 | AF24: #2b9800 | AG24: #000000 | AH24: #2b9800 | AI24: #2b9800 | AJ24: #2b9800 | AK24: {=INDEX(Factions!C:C, MATCH(E24, Factions!B:B, 0))} -> #ffb317 | AL24: {=INDEX(Factions!D:D, MATCH(E24, Factions!B:B, 0))} -> #cf6c23 | AM24: {=INDEX(Factions!E:E, MATCH(E24, Factions!B:B, 0))} -> #000000 | AN24: {=INDEX(Factions!F:F, MATCH(E24, Factions!B:B, 0))} -> #ffffff | AO24: {=concat(INDEX(Factions!G:G, MATCH(E24, Factions!B:B, 0)),".png")} -> gremlins.png | AP24: =IFERROR(__xludf.DUMMYFUNCTION("MIN(FILTER(M24:M1098, F24:F1098=F24))"),2.0) -> 2 | AQ24: =Q24*L24 -> 5 | AR24: =IFERROR(__xludf.DUMMYFUNCTION("IF(and(REGEXMATCH(S24,""Vengence""),not(REGEXMATCH(S24, ""Protective Markings""))),AQ24,AQ24 * 6 / iferror(R24-1,6))"),10.0) -> 10 | AS24: =0 + if(P24="2d6",7,if(P24="d6",3.5,if(P24="d3",1.5,if(P24="2x2",4,if(P24="2x3",6,P24))))) -> 5 | AT24: =AS24*L24 -> 5 | AU24: =IFERROR(__xludf.DUMMYFUNCTION("IF(REGEXMATCH(S24,""<b>Poison</b>""),1+((1/(7-N24))/3),1)"),1.0) -> 1 | AV24: =IFERROR(__xludf.DUMMYFUNCTION("IF(REGEXMATCH(S24,""Vengence""),(7 - R24) / 3,0)"),0.0) -> 0 | AW24: =AV24 + (AT24*(7-N24)/6)*AU24 -> 3.3333333 | AX24: =AR24+(AW24*1.5) -> 15 | AY24: =IFERROR(__xludf.DUMMYFUNCTION("if(regexmatch(G24,""Mage|War Machine""),true,false)"),FALSE) -> FALSE
A25: 06_2C_2 | B25: Hookshot | C25: =concatenate(E25," ",B25) -> Coppersand Hookshot | D25: TRUE | E25: Coppersand | F25: Artillery | G25: War Machine | H25: 6 | I25: 2 | L25: 1 | M25: 1 | N25: 5 | O25: 4 | P25: 2 | Q25: 3 | R25: 4 | S25: <b>Construct</b> - Immune to fear checks while adjacent to a mechanic. Dies if it flees. <b>War Machine</b> - Dies if it flees. <b>Hookshot</b> - Ranged Weapon. Range 5. Fires 4 shots. If any shots hit (they can be blocked), move the target unit one square towards this unit. | T25: 2 | AE25: #000000 | AF25: #000000 | AG25: #2b9800 | AH25: #000000 | AI25: #000000 | AJ25: #2b9800 | AK25: {=INDEX(Factions!C:C, MATCH(E25, Factions!B:B, 0))} -> #ffb317 | AL25: {=INDEX(Factions!D:D, MATCH(E25, Factions!B:B, 0))} -> #cf6c23 | AM25: {=INDEX(Factions!E:E, MATCH(E25, Factions!B:B, 0))} -> #000000 | AN25: {=INDEX(Factions!F:F, MATCH(E25, Factions!B:B, 0))} -> #ffffff | AO25: {=concat(INDEX(Factions!G:G, MATCH(E25, Factions!B:B, 0)),".png")} -> gremlins.png | AP25: =IFERROR(__xludf.DUMMYFUNCTION("MIN(FILTER(M25:M1098, F25:F1098=F25))"),1.0) -> 1 | AQ25: =Q25*L25 -> 3 | AR25: =IFERROR(__xludf.DUMMYFUNCTION("IF(and(REGEXMATCH(S25,""Vengence""),not(REGEXMATCH(S25, ""Protective Markings""))),AQ25,AQ25 * 6 / iferror(R25-1,6))"),6.0) -> 6 | AS25: =0 + if(P25="2d6",7,if(P25="d6",3.5,if(P25="d3",1.5,if(P25="2x2",4,if(P25="2x3",6,P25))))) -> 2 | AT25: =AS25*L25 -> 2 | AU25: =IFERROR(__xludf.DUMMYFUNCTION("IF(REGEXMATCH(S25,""<b>Poison</b>""),1+((1/(7-N25))/3),1)"),1.0) -> 1 | AV25: =IFERROR(__xludf.DUMMYFUNCTION("IF(REGEXMATCH(S25,""Vengence""),(7 - R25) / 3,0)"),0.0) -> 0 | AW25: =AV25 + (AT25*(7-N25)/6)*AU25 -> 0.66666667 | AX25: =AR25+(AW25*1.5) -> 7 | AY25: =IFERROR(__xludf.DUMMYFUNCTION("if(regexmatch(G25,""Mage|War Machine""),true,false)"),TRUE) -> TRUE
A26: 06_2B_2 | B26: Overseer | C26: =concatenate(E26," ",B26) -> Coppersand Overseer | D26: TRUE | E26: Coppersand | F26: Colossus | G26: Monster | H26: 5 | I26: 2 | L26: 1 | M26: 2 | N26: 4 | O26: 4 | P26: 4 | Q26: 5 | R26: 5 | S26: <b>Construct</b> - Immune to fear checks while adjacent to a mechanic. Dies if it flees. <b>Multishot 3</b> - Ranged attacks roll 3 dice. <b>Overwatch</b> - During your opponent's turn, fire a round of shooting at the first enemy unit to become a new valid shooting target. Has no effect on units that were already valid shooting targets. This can take effect because of units fleeing combat or getting wiped out. <b>Prepared Ranged Weapon</b> - Equip this unit with one free common or uncommon ranged weapon. | T26: 3.25 | AC26: 1 | AD26: 2 | AE26: #2b9800 | AF26: #000000 | AG26: #2b9800 | AH26: #000000 | AI26: #2b9800 | AJ26: #000000 | AK26: {=INDEX(Factions!C:C, MATCH(E26, Factions!B:B, 0))} -> #ffb317 | AL26: {=INDEX(Factions!D:D, MATCH(E26, Factions!B:B, 0))} -> #cf6c23 | AM26: {=INDEX(Factions!E:E, MATCH(E26, Factions!B:B, 0))} -> #000000 | AN26: {=INDEX(Factions!F:F, MATCH(E26, Factions!B:B, 0))} -> #ffffff | AO26: {=concat(INDEX(Factions!G:G, MATCH(E26, Factions!B:B, 0)),".png")} -> gremlins.png | AP26: =IFERROR(__xludf.DUMMYFUNCTION("MIN(FILTER(M26:M1098, F26:F1098=F26))"),2.0) -> 2 | AQ26: =Q26*L26 -> 5 | AR26: =IFERROR(__xludf.DUMMYFUNCTION("IF(and(REGEXMATCH(S26,""Vengence""),not(REGEXMATCH(S26, ""Protective Markings""))),AQ26,AQ26 * 6 / iferror(R26-1,6))"),7.5) -> 7.5 | AS26: =0 + if(P26="2d6",7,if(P26="d6",3.5,if(P26="d3",1.5,if(P26="2x2",4,if(P26="2x3",6,P26))))) -> 4 | AT26: =AS26*L26 -> 4 | AU26: =IFERROR(__xludf.DUMMYFUNCTION("IF(REGEXMATCH(S26,""<b>Poison</b>""),1+((1/(7-N26))/3),1)"),1.0) -> 1 | AV26: =IFERROR(__xludf.DUMMYFUNCTION("IF(REGEXMATCH(S26,""Vengence""),(7 - R26) / 3,0)"),0.0) -> 0 | AW26: =AV26 + (AT26*(7-N26)/6)*AU26 -> 2 | AX26: =AR26+(AW26*1.5) -> 10.5 | AY26: =IFERROR(__xludf.DUMMYFUNCTION("if(regexmatch(G26,""Mage|War Machine""),true,false)"),FALSE) -> FALSE
A27: 06_2A_1 | B27: Clay Golems | C27: =concatenate(E27," ",B27) -> Coppersand Clay Golems | D27: TRUE | E27: Coppersand | F27: Golems | G27: Heavy Infantry | H27: 5 | I27: 2 | L27: 3 | M27: 1 | N27: 4 | O27: - | P27: 2 | Q27: 3 | R27: 5 | S27: <b>Construct</b> - Immune to fear checks while adjacent to a mechanic. Dies if it flees. <b>Regenerative Clay</b> - At the end of each player's turn, each model heals to full. This does not ressurect dead models. <b>Multiwound 2</b> - Each hit does 2 wounds to a single model. | T27: 7.25 | AA27: 3 | AC27: 2 | AE27: #000000 | AF27: #000000 | AG27: #000000 | AH27: #000000 | AI27: #2b9800 | AJ27: #000000 | AK27: {=INDEX(Factions!C:C, MATCH(E27, Factions!B:B, 0))} -> #ffb317 | AL27: {=INDEX(Factions!D:D, MATCH(E27, Factions!B:B, 0))} -> #cf6c23 | AM27: {=INDEX(Factions!E:E, MATCH(E27, Factions!B:B, 0))} -> #000000 | AN27: {=INDEX(Factions!F:F, MATCH(E27, Factions!B:B, 0))} -> #ffffff | AO27: {=concat(INDEX(Factions!G:G, MATCH(E27, Factions!B:B, 0)),".png")} -> gremlins.png | AP27: =IFERROR(__xludf.DUMMYFUNCTION("MIN(FILTER(M27:M1098, F27:F1098=F27))"),1.0) -> 1 | AQ27: =Q27*L27 -> 9 | AR27: =IFERROR(__xludf.DUMMYFUNCTION("IF(and(REGEXMATCH(S27,""Vengence""),not(REGEXMATCH(S27, ""Protective Markings""))),AQ27,AQ27 * 6 / iferror(R27-1,6))"),13.5) -> 13.5 | AS27: =0 + if(P27="2d6",7,if(P27="d6",3.5,if(P27="d3",1.5,if(P27="2x2",4,if(P27="2x3",6,P27))))) -> 2 | AT27: =AS27*L27 -> 6 | AU27: =IFERROR(__xludf.DUMMYFUNCTION("IF(REGEXMATCH(S27,""<b>Poison</b>""),1+((1/(7-N27))/3),1)"),1.0) -> 1 | AV27: =IFERROR(__xludf.DUMMYFUNCTION("IF(REGEXMATCH(S27,""Vengence""),(7 - R27) / 3,0)"),0.0) -> 0 | AW27: =AV27 + (AT27*(7-N27)/6)*AU27 -> 3 | AX27: =AR27+(AW27*1.5) -> 18 | AY27: =IFERROR(__xludf.DUMMYFUNCTION("if(regexmatch(G27,""Mage|War Machine""),true,false)"),FALSE) -> FALSE
A28: 06_2A_2 | B28: Minetomatons | C28: =concatenate(E28," ",B28) -> Coppersand Minetomatons | D28: TRUE | E28: Coppersand | F28: Golems | G28: Unique | H28: 5 | I28: 2 | L28: 3 | M28: 1 | N28: 4 | O28: - | P28: 2 | Q28: 2 | R28: 5 | S28: <b>Construct</b> - Immune to fear checks while adjacent to a mechanic. Dies if it flees. <b>Ambush</b> - Action: Remove this unit from the board. On your next turn, place it on an empty space along any board edge (facing away from the board edge) as its action for the turn <b>AP 1</b> - Reduce block rolls by 1. | T28: 5 | Z28: 3 | AA28: 3 | AE28: #000000 | AF28: #000000 | AG28: #000000 | AH28: #000000 | AI28: #000000 | AJ28: #000000 | AK28: {=INDEX(Factions!C:C, MATCH(E28, Factions!B:B, 0))} -> #ffb317 | AL28: {=INDEX(Factions!D:D, MATCH(E28, Factions!B:B, 0))} -> #cf6c23 | AM28: {=INDEX(Factions!E:E, MATCH(E28, Factions!B:B, 0))} -> #000000 | AN28: {=INDEX(Factions!F:F, MATCH(E28, Factions!B:B, 0))} -> #ffffff | AO28: {=concat(INDEX(Factions!G:G, MATCH(E28, Factions!B:B, 0)),".png")} -> gremlins.png | AP28: =IFERROR(__xludf.DUMMYFUNCTION("MIN(FILTER(M28:M1098, F28:F1098=F28))"),1.0) -> 1 | AQ28: =Q28*L28 -> 6 | AR28: =IFERROR(__xludf.DUMMYFUNCTION("IF(and(REGEXMATCH(S28,""Vengence""),not(REGEXMATCH(S28, ""Protective Markings""))),AQ28,AQ28 * 6 / iferror(R28-1,6))"),9.0) -> 9 | AS28: =0 + if(P28="2d6",7,if(P28="d6",3.5,if(P28="d3",1.5,if(P28="2x2",4,if(P28="2x3",6,P28))))) -> 2 | AT28: =AS28*L28 -> 6 | AU28: =IFERROR(__xludf.DUMMYFUNCTION("IF(REGEXMATCH(S28,""<b>Poison</b>""),1+((1/(7-N28))/3),1)"),1.0) -> 1 | AV28: =IFERROR(__xludf.DUMMYFUNCTION("IF(REGEXMATCH(S28,""Vengence""),(7 - R28) / 3,0)"),0.0) -> 0 | AW28: =AV28 + (AT28*(7-N28)/6)*AU28 -> 3 | AX28: =AR28+(AW28*1.5) -> 13.5 | AY28: =IFERROR(__xludf.DUMMYFUNCTION("if(regexmatch(G28,""Mage|War Machine""),true,false)"),FALSE) -> FALSE
A29: 06_2A_3 | B29: Bladestorms | C29: =concatenate(E29," ",B29) -> Coppersand Bladestorms | D29: TRUE | E29: Coppersand | F29: Golems | G29: Attack Infantry | H29: 5 | I29: 2 | L29: 3 | M29: 1 | N29: 5 | O29: - | P29: 2x2 | Q29: 2 | R29: 5 | S29: <b>Construct</b> - Immune to fear checks while adjacent to a mechanic. Dies if it flees. <b>Four Arms</b> - Wields two sets of weapons. This unit performs a round of attacks with one set of weapons, then a second round of attacks with a second set of weapons. <b>Prepared Weapons</b> - Equip this unit with one free uncommon weapon, or two free common weapons. | T29: 5.5 | U29: <b>AP 1</b> | Y29: 2 | Z29: 2 | AA29: 2 | AB29: 2 | AE29: #000000 | AF29: #cc0000 | AG29: #000000 | AH29: #3467FF | AI29: #000000 | AJ29: #000000 | AK29: {=INDEX(Factions!C:C, MATCH(E29, Factions!B:B, 0))} -> #ffb317 | AL29: {=INDEX(Factions!D:D, MATCH(E29, Factions!B:B, 0))} -> #cf6c23 | AM29: {=INDEX(Factions!E:E, MATCH(E29, Factions!B:B, 0))} -> #000000 | AN29: {=INDEX(Factions!F:F, MATCH(E29, Factions!B:B, 0))} -> #ffffff | AO29: {=concat(INDEX(Factions!G:G, MATCH(E29, Factions!B:B, 0)),".png")} -> gremlins.png | AP29: =IFERROR(__xludf.DUMMYFUNCTION("MIN(FILTER(M29:M1098, F29:F1098=F29))"),1.0) -> 1 | AQ29: =Q29*L29 -> 6 | AR29: =IFERROR(__xludf.DUMMYFUNCTION("IF(and(REGEXMATCH(S29,""Vengence""),not(REGEXMATCH(S29, ""Protective Markings""))),AQ29,AQ29 * 6 / iferror(R29-1,6))"),9.0) -> 9 | AS29: =0 + if(P29="2d6",7,if(P29="d6",3.5,if(P29="d3",1.5,if(P29="2x2",4,if(P29="2x3",6,P29))))) -> 4 | AT29: =AS29*L29 -> 12 | AU29: =IFERROR(__xludf.DUMMYFUNCTION("IF(REGEXMATCH(S29,""<b>Poison</b>""),1+((1/(7-N29))/3),1)"),1.0) -> 1 | AV29: =IFERROR(__xludf.DUMMYFUNCTION("IF(REGEXMATCH(S29,""Vengence""),(7 - R29) / 3,0)"),0.0) -> 0 | AW29: =AV29 + (AT29*(7-N29)/6)*AU29 -> 4 | AX29: =AR29+(AW29*1.5) -> 15 | AY29: =IFERROR(__xludf.DUMMYFUNCTION("if(regexmatch(G29,""Mage|War Machine""),true,false)"),FALSE) -> FALSE
A30: 06_2C_3 | B30: Surpressor | C30: =concatenate(E30," ",B30) -> Coppersand Surpressor | D30: TRUE | E30: Coppersand | F30: Artillery | G30: War Machine | H30: 6 | I30: 2 | L30: 1 | M30: 1 | N30: 6 | O30: - | P30: 2 | Q30: 4 | R30: 6 | S30: <b>Construct</b> - Immune to fear checks while adjacent to a mechanic. Dies if it flees. <b>War Machine</b> - Dies if it flees. <b>Surpression Cannon</b> - Target a square in shooting range 5. Each unit in that firing line at the start of your next turn takes 5 ranged attacks hitting on 3+ with AP3. May not target a firing line that includes a friendly unit, but will hit them if they move in before your turn ends. | T30: 1 | AE30: #000000 | AF30: #000000 | AG30: #000000 | AH30: #000000 | AI30: #000000 | AJ30: #000000 | AK30: {=INDEX(Factions!C:C, MATCH(E30, Factions!B:B, 0))} -> #ffb317 | AL30: {=INDEX(Factions!D:D, MATCH(E30, Factions!B:B, 0))} -> #cf6c23 | AM30: {=INDEX(Factions!E:E, MATCH(E30, Factions!B:B, 0))} -> #000000 | AN30: {=INDEX(Factions!F:F, MATCH(E30, Factions!B:B, 0))} -> #ffffff | AO30: {=concat(INDEX(Factions!G:G, MATCH(E30, Factions!B:B, 0)),".png")} -> gremlins.png | AP30: =IFERROR(__xludf.DUMMYFUNCTION("MIN(FILTER(M30:M1098, F30:F1098=F30))"),1.0) -> 1 | AQ30: =Q30*L30 -> 4 | AR30: =IFERROR(__xludf.DUMMYFUNCTION("IF(and(REGEXMATCH(S30,""Vengence""),not(REGEXMATCH(S30, ""Protective Markings""))),AQ30,AQ30 * 6 / iferror(R30-1,6))"),4.8) -> 4.8 | AS30: =0 + if(P30="2d6",7,if(P30="d6",3.5,if(P30="d3",1.5,if(P30="2x2",4,if(P30="2x3",6,P30))))) -> 2 | AT30: =AS30*L30 -> 2 | AU30: =IFERROR(__xludf.DUMMYFUNCTION("IF(REGEXMATCH(S30,""<b>Poison</b>""),1+((1/(7-N30))/3),1)"),1.0) -> 1 | AV30: =IFERROR(__xludf.DUMMYFUNCTION("IF(REGEXMATCH(S30,""Vengence""),(7 - R30) / 3,0)"),0.0) -> 0 | AW30: =AV30 + (AT30*(7-N30)/6)*AU30 -> 0.33333333 | AX30: =AR30+(AW30*1.5) -> 5.3 | AY30: =IFERROR(__xludf.DUMMYFUNCTION("if(regexmatch(G30,""Mage|War Machine""),true,false)"),TRUE) -> TRUE
A31: 06_2C_1 | B31: Grand Bombard | C31: =concatenate(E31," ",B31) -> Coppersand Grand Bombard | D31: TRUE | E31: Coppersand | F31: Artillery | G31: War Machine | H31: 6 | I31: 2 | L31: 1 | M31: 1 | N31: 6 | O31: - | P31: 2 | Q31: 3 | R31: 6 | S31: <b>Construct</b> - Immune to fear checks while adjacent to a mechanic. Dies if it flees. <b>War Machine</b> - Dies if it flees. <b>Primed</b> - Place 2 powder tokens on this when it is revealed. <b>Reloading</b> - Place a powder tokens on this unit at the end of your turn. <b>Bombard</b> - Action: Uses all powder tokens as X. Pick a target square within 2 + X, roll a die and add X. 7+ - Direct hit. 5-6 - Off by one towards your board edge. 4 or less - Miss. Keep all powder tokens. Any unit in the hit square takes 3X attacks hitting on 3+ with AP X. Lose all powder tokens. | T31: 1 | AE31: #000000 | AF31: #000000 | AG31: #000000 | AH31: #000000 | AI31: #000000 | AJ31: #000000 | AK31: {=INDEX(Factions!C:C, MATCH(E31, Factions!B:B, 0))} -> #ffb317 | AL31: {=INDEX(Factions!D:D, MATCH(E31, Factions!B:B, 0))} -> #cf6c23 | AM31: {=INDEX(Factions!E:E, MATCH(E31, Factions!B:B, 0))} -> #000000 | AN31: {=INDEX(Factions!F:F, MATCH(E31, Factions!B:B, 0))} -> #ffffff | AO31: {=concat(INDEX(Factions!G:G, MATCH(E31, Factions!B:B, 0)),".png")} -> gremlins.png | AP31: =IFERROR(__xludf.DUMMYFUNCTION("MIN(FILTER(M31:M1098, F31:F1098=F31))"),1.0) -> 1 | AQ31: =Q31*L31 -> 3 | AR31: =IFERROR(__xludf.DUMMYFUNCTION("IF(and(REGEXMATCH(S31,""Vengence""),not(REGEXMATCH(S31, ""Protective Markings""))),AQ31,AQ31 * 6 / iferror(R31-1,6))"),3.6) -> 3.6 | AS31: =0 + if(P31="2d6",7,if(P31="d6",3.5,if(P31="d3",1.5,if(P31="2x2",4,if(P31="2x3",6,P31))))) -> 2 | AT31: =AS31*L31 -> 2 | AU31: =IFERROR(__xludf.DUMMYFUNCTION("IF(REGEXMATCH(S31,""<b>Poison</b>""),1+((1/(7-N31))/3),1)"),1.0) -> 1 | AV31: =IFERROR(__xludf.DUMMYFUNCTION("IF(REGEXMATCH(S31,""Vengence""),(7 - R31) / 3,0)"),0.0) -> 0 | AW31: =AV31 + (AT31*(7-N31)/6)*AU31 -> 0.33333333 | AX31: =AR31+(AW31*1.5) -> 4.1 | AY31: =IFERROR(__xludf.DUMMYFUNCTION("if(regexmatch(G31,""Mage|War Machine""),true,false)"),TRUE) -> TRUE
A32: 08_1_2 | B32: Ratbeasts | C32: =concatenate(E32," ",B32) -> Disciples Ratbeasts | D32: TRUE | E32: Disciples | F32: Mongrels | G32: Chaff | H32: 5 | I32: 1 | J32: 1 | L32: 3 | M32: 1 | N32: 6 | O32: - | P32: 3 | Q32: 2 | R32: - | S32: <b>Chaff</b> - Subtract 1 from leadership rolls. 6s still auto-succeed. <b>Unprotected</b> - Reveal this unit when an attack hits it, rather than using the default block. | T32: 3 | Y32: 1 | AC32: 1 | AE32: #000000 | AF32: #cc0000 | AG32: #000000 | AH32: #2b9800 | AI32: #000000 | AJ32: #cc0000 | AK32: {=INDEX(Factions!C:C, MATCH(E32, Factions!B:B, 0))} -> #5c9667 | AL32: {=INDEX(Factions!D:D, MATCH(E32, Factions!B:B, 0))} -> #005050 | AM32: {=INDEX(Factions!E:E, MATCH(E32, Factions!B:B, 0))} -> #000000 | AN32: {=INDEX(Factions!F:F, MATCH(E32, Factions!B:B, 0))} -> #ffffff | AO32: {=concat(INDEX(Factions!G:G, MATCH(E32, Factions!B:B, 0)),".png")} -> disciples.png | AP32: =IFERROR(__xludf.DUMMYFUNCTION("MIN(FILTER(M32:M1098, F32:F1098=F32))"),1.0) -> 1 | AQ32: =Q32*L32 -> 6 | AR32: =IFERROR(__xludf.DUMMYFUNCTION("IF(and(REGEXMATCH(S32,""Vengence""),not(REGEXMATCH(S32, ""Protective Markings""))),AQ32,AQ32 * 6 / iferror(R32-1,6))"),6.0) -> 6 | AS32: =0 + if(P32="2d6",7,if(P32="d6",3.5,if(P32="d3",1.5,if(P32="2x2",4,if(P32="2x3",6,P32))))) -> 3 | AT32: =AS32*L32 -> 9 | AU32: =IFERROR(__xludf.DUMMYFUNCTION("IF(REGEXMATCH(S32,""<b>Poison</b>""),1+((1/(7-N32))/3),1)"),1.0) -> 1 | AV32: =IFERROR(__xludf.DUMMYFUNCTION("IF(REGEXMATCH(S32,""Vengence""),(7 - R32) / 3,0)"),0.0) -> 0 | AW32: =AV32 + (AT32*(7-N32)/6)*AU32 -> 1.5 | AX32: =AR32+(AW32*1.5) -> 8.25 | AY32: =IFERROR(__xludf.DUMMYFUNCTION("if(regexmatch(G32,""Mage|War Machine""),true,false)"),FALSE) -> FALSE
A33: 08_1_3 | B33: Scalebeasts | C33: =concatenate(E33," ",B33) -> Disciples Scalebeasts | D33: TRUE | E33: Disciples | F33: Mongrels | G33: Heavy Infantry | H33: 5 | I33: 1 | J33: 2 | L33: 3 | M33: 1 | N33: 5 | O33: - | P33: 2 | Q33: 2 | R33: 4 | S33: <b>Shieldwall</b> - Improve block by 1 against ranged attacks | T33: 4 | Y33: 1 | Z33: 1 | AA33: 1 | AB33: 1 | AC33: 1 | AE33: #000000 | AF33: #cc0000 | AG33: #000000 | AH33: #2b9800 | AI33: #000000 | AJ33: #2b9800 | AK33: {=INDEX(Factions!C:C, MATCH(E33, Factions!B:B, 0))} -> #5c9667 | AL33: {=INDEX(Factions!D:D, MATCH(E33, Factions!B:B, 0))} -> #005050 | AM33: {=INDEX(Factions!E:E, MATCH(E33, Factions!B:B, 0))} -> #000000 | AN33: {=INDEX(Factions!F:F, MATCH(E33, Factions!B:B, 0))} -> #ffffff | AO33: {=concat(INDEX(Factions!G:G, MATCH(E33, Factions!B:B, 0)),".png")} -> disciples.png | AP33: =IFERROR(__xludf.DUMMYFUNCTION("MIN(FILTER(M33:M1098, F33:F1098=F33))"),1.0) -> 1 | AQ33: =Q33*L33 -> 6 | AR33: =IFERROR(__xludf.DUMMYFUNCTION("IF(and(REGEXMATCH(S33,""Vengence""),not(REGEXMATCH(S33, ""Protective Markings""))),AQ33,AQ33 * 6 / iferror(R33-1,6))"),12.0) -> 12 | AS33: =0 + if(P33="2d6",7,if(P33="d6",3.5,if(P33="d3",1.5,if(P33="2x2",4,if(P33="2x3",6,P33))))) -> 2 | AT33: =AS33*L33 -> 6 | AU33: =IFERROR(__xludf.DUMMYFUNCTION("IF(REGEXMATCH(S33,""<b>Poison</b>""),1+((1/(7-N33))/3),1)"),1.0) -> 1 | AV33: =IFERROR(__xludf.DUMMYFUNCTION("IF(REGEXMATCH(S33,""Vengence""),(7 - R33) / 3,0)"),0.0) -> 0 | AW33: =AV33 + (AT33*(7-N33)/6)*AU33 -> 2 | AX33: =AR33+(AW33*1.5) -> 15 | AY33: =IFERROR(__xludf.DUMMYFUNCTION("if(regexmatch(G33,""Mage|War Machine""),true,false)"),FALSE) -> FALSE
A34: 08_1_1 | B34: Warriors | C34: =concatenate(E34," ",B34) -> Disciples Warriors | D34: TRUE | E34: Disciples | F34: Mongrels | G34: Warriors | H34: 5 | I34: 1 | J34: 2 | L34: 3 | M34: 1 | N34: 4 | O34: 6 | P34: 2 | Q34: 2 | R34: 5 | S34: <b>Multishot 2</b> - Ranged attacks roll 2 dice. | T34: 4 | Y34: 1 | Z34: 1 | AA34: 1 | AB34: 1 | AC34: 1 | AD34: 1 | AE34: #000000 | AF34: #000000 | AG34: #000000 | AH34: #2b9800 | AI34: #000000 | AJ34: #000000 | AK34: {=INDEX(Factions!C:C, MATCH(E34, Factions!B:B, 0))} -> #5c9667 | AL34: {=INDEX(Factions!D:D, MATCH(E34, Factions!B:B, 0))} -> #005050 | AM34: {=INDEX(Factions!E:E, MATCH(E34, Factions!B:B, 0))} -> #000000 | AN34: {=INDEX(Factions!F:F, MATCH(E34, Factions!B:B, 0))} -> #ffffff | AO34: {=concat(INDEX(Factions!G:G, MATCH(E34, Factions!B:B, 0)),".png")} -> disciples.png | AP34: =IFERROR(__xludf.DUMMYFUNCTION("MIN(FILTER(M34:M1098, F34:F1098=F34))"),1.0) -> 1 | AQ34: =Q34*L34 -> 6 | AR34: =IFERROR(__xludf.DUMMYFUNCTION("IF(and(REGEXMATCH(S34,""Vengence""),not(REGEXMATCH(S34, ""Protective Markings""))),AQ34,AQ34 * 6 / iferror(R34-1,6))"),9.0) -> 9 | AS34: =0 + if(P34="2d6",7,if(P34="d6",3.5,if(P34="d3",1.5,if(P34="2x2",4,if(P34="2x3",6,P34))))) -> 2 | AT34: =AS34*L34 -> 6 | AU34: =IFERROR(__xludf.DUMMYFUNCTION("IF(REGEXMATCH(S34,""<b>Poison</b>""),1+((1/(7-N34))/3),1)"),1.0) -> 1 | AV34: =IFERROR(__xludf.DUMMYFUNCTION("IF(REGEXMATCH(S34,""Vengence""),(7 - R34) / 3,0)"),0.0) -> 0 | AW34: =AV34 + (AT34*(7-N34)/6)*AU34 -> 3 | AX34: =AR34+(AW34*1.5) -> 13.5 | AY34: =IFERROR(__xludf.DUMMYFUNCTION("if(regexmatch(G34,""Mage|War Machine""),true,false)"),FALSE) -> FALSE
